Workbook

Sheet Dashboard
A1: Tableau de Bord Synthese
A2: Synthese en une page pour les investisseurs et partenaires : chiffres cles, trajectoire et principes de base.
A4: Chiffre d'affaires annee 1 | B4: 1793550 | D4: Synthese executive
A5: Marge brute annee 1 | B5: 0.69463076 | D5: Forge est notre moteur de cash immediat.
A6: EBITDA annee 1 | B6: 309855 | D6: Sovereign est notre developpement technologique strategique.
A7: Mois d'equilibre (Break-even) | B7: 4 | D7: Le modele est conçu pour etre commando (lean) puis scalable.
A8: CA mensuel cible (Mois 36) | B8: 531625 | D8: Les tarifs sont en ZAR, la TVA est exclue des marges de profit.
A9: Tresorerie finale (Mois 36) | B9: 4131725 | D9: L'impot sur les societes (IS) est modelise a 27%.
D10: Message cle : Opays Tech est un systeme d'exploitation d'efficience au service des clients.

Sheet README
A1: Classeur Investisseur Opays Tech
A2: Un outil unique regroupant la strategie, le modele financier, la gestion des risques et la preparation operationnelle.
A4: • Objectif : Structurer le developpement d'Opays Tech en un modele operationnel et financier robuste, sans surevaluation.
A5: • Narratif : Forge = moteur de cash, Sovereign = developpement d'actifs et R&D, le tout pilote par un systeme d'exploitation lean.
A6: • Devise : Rand sud-africain (ZAR).
A7: • Remarque fiscale importante : Le modele applique de maniere prudente les regles fiscales standards et comptabilise la TVA separement.
A8: • Utilisation : Consultez d'abord le Tableau de bord, puis les Hypotheses, puis les details financiers et operationnels pour la livraison.
A11: Onglets inclus dans ce classeur :
A12: - Dashboard
A13: - Assumptions
A14: - Offers
A15: - GTM
... A34: - Investor_QA

Sheet Assumptions
A1: Hypotheses generales
A2: Entrees modifiables. Ajustez ces valeurs pour adapter ou localiser le modele.
A4: Devise de reference | B4: ZAR
A5: Debut des previsions | B5: 46174
A6: Duree des previsions (mois) | B6: 36
A7: Taux de TVA | B7: 0.15
A8: Taux d'impot sur les societes | B8: 0.27
A9: Tresorerie initiale | B9: 250000
A10: Cible de financement recommandee (Seed) | B10: 1200000
A11: Investissement initial (Mois 1) | B11: 60000
A13: Modele des Offres
A14: Offre | B14: Tarif (ZAR) | C14: Cout direct | D14: Marge brute | E14: Remarques
A15: Audit / Diagnostic | B15: 25000 | C15: 0.15 | D15: =1-C15 | E15: Offre d'entree pour identifier le ROI et les goulots d'etranglement.
A16: Sprint d'Efficience | B16: 75000 | C16: 0.3 | D16: =1-C16 | E16: Sprint court d'implementation, generalement 2-4 semaines.
A17: Projet d'Implementation | B17: 180000 | C17: 0.45 | D17: =1-C17 | E17: Execution a haute valeur sur un flux de travail ou systeme client.
A18: Forge Retainer (Accompagnement) | B18: 30000 | C18: 0.2 | D18: =1-C18 | E18: Optimisation recurrente et support operationnel continu.
A19: Sovereign Retainer (R&D) | B19: 45000 | C19: 0.5 | D19: =1-C19 | E19: Travaux de R&D, d'autonomie et de resilience strategique.
A20: Dossier Sovereign | B20: 120000 | C20: 0.5 | D20: =1-C20 | E20: Recherche strategique ponctuelle, note de synthese ou feuille de route.
A23: Facteurs de croissance
A24: Offre | B24: Unites initiales | C24: Croissance mensuelle | D24: Plafond
A25: Audit / Diagnostic | B25: 1 | C25: 0.06 | D25: 3.5
A26: Sprint d'Efficience | B26: 0.3 | C26: 0.025 | D26: 1.4
A27: Projet d'Implementation | B27: 0.05 | C27: 0.02 | D27: 0.85
A28: Forge Retainer (Accompagnement) | B28: 0.5 | C28: 0.1 | D28: 4
A29: Sovereign Retainer (R&D) | B29: 0 | C29: 0.04 | D29: 1.8
A30: Dossier Sovereign | B30: 0 | C30: 0.02 | D30: 0.4
A33: Phases d'Opex fixes
A34: Categorie d'Opex | B34: Mois 1-12 | C34: Mois 13-24 | D34: Mois 25-36
A35: Remuneration Fondateur / CEO | B35: 30000 | C35: 33000 | D35: 36000
A36: Support Operations & Gestion | B36: 10000 | C36: 12000 | D36: 14000
A37: Marketing & Contenu | B37: 10000 | C37: 12000 | D37: 16000
A38: Outils SaaS & Logiciels | B38: 5000 | C38: 6000 | D38: 7000
A39: Deplacements & Livraison client | B39: 6000 | C39: 7000 | D39: 8000
A40: Frais Juridiques, Comptables & Conformite | B40: 4500 | C40: 5000 | D40: 6000
A41: Admin, Internet & Telecoms | B41: 3500 | C41: 4000 | D41: 4500
A42: Reserve Imprevus / Contingence | B42: 4000 | C42: 4000 | D42: 5000
A43: Reserve Recrutement / Croissance | B43: 5000 | C43: 15000 | D43: 22000
A46: Hypotheses Go-To-Market
A47: Canal | B47: Objectif | C47: Activite mensuelle | D47: Taux Prospect | E47: Taux Appel | F47: Taux Closing | G47: Notes
A48: Page entreprise LinkedIn | B48: Notoriete et autorite intellectuelle | C48: 8000 | D48: 2.5 | E48: 12 | F48: 35 | G48: 30 | H48: Canal principal de sensibilisation
...

Sheet Offers
A1: Architecture des Offres
A2: Offres productisees avec tarifications, livraison et marges conservatives.
A4: Offre | B4: Tarif (ZAR) | C4: Cout direct % | D4: Marge brute % | E4: Probleme client traite | F4: Notes de livraison
A5: Audit / Diagnostic | B5: 25000 | C5: 0.15 | D5: =1-C5 | E5: Identifier les goulots d'etranglement, cartographier les frictions et reveler le ROI. | F5: Offre d'entree pour identifier le ROI et les goulots d'etranglement.
A6: Sprint d'Efficience | B6: 75000 | C6: 0.3 | D6: =1-C6 | E6: Resoudre un probleme precis de flux de travail rapidement et de maniere visible. | F6: Sprint court d'implementation, generalement 2-4 semaines.
A7: Projet d'Implementation | B7: 180000 | C7: 0.45 | D7: =1-C7 | E7: Transformer durablement un flux de travail ou integrer un systeme sur mesure. | F7: Execution a haute valeur sur un flux de travail ou systeme client.
A8: Forge Retainer (Accompagnement) | B8: 30000 | C8: 0.2 | D8: =1-C8 | E8: Fournir un support et une optimisation continue des systemes installes. | F8: Optimisation recurrente et support operationnel continu.
A9: Sovereign Retainer (R&D) | B9: 45000 | C9: 0.5 | D9: =1-C9 | E9: Soutenir la resilience strategique et l'autonomie technologique locale. | F9: Travaux de R&D, d'autonomie et de resilience strategique.
A10: Dossier Sovereign | B10: 120000 | C10: 0.5 | D10: =1-C10 | E10: Fournir une recherche strategique approfondie ou une note de synthese prete pour le Board. | F10: Recherche strategique ponctuelle, note de synthese ou feuille de route.

Sheet GTM
A1: Go-to-Market et Funnel
A2: Un entonnoir de conversion pragmatique : attention -> audit -> sprint -> projet -> retainer.
A4: Canal | B4: Objectif | C4: Activite mensuelle | D4: Taux Prospect | E4: Taux Appel | F4: Taux Closing (Audit) | G4: Taux Signature | H4: Commentaire
A5: Page entreprise LinkedIn | B5: Notoriete et autorite intellectuelle | C5: 8000 | D5: 0.025 | E5: 0.12 | F5: 0.35 | G5: 0.3 | H5: Canal principal de sensibilisation
A6: Medias locaux | B6: Confiance et legitimite locale | C6: 1000 | D6: 0.08 | E6: 0.25 | F6: 0.4 | G6: 0.35 | H6: Visibilite trimestrielle, credibilite accrue
A7: Recommandations / Partenaires | B7: Opportunites entrantes a forte confiance | C7: 5 | D7: 1 | E7: 1 | F7: 0.8 | G7: 0.5 | H7: Taux de closing le plus eleve
A8: Prospection directe | B8: Demarchage cible | C8: 40 | D8: 0.1 | E8: 0.6 | F8: 0.25 | G8: 0.4 | H8: Generation active de pipeline
A11: Constat pragmatique | B11: Le modele de developpement ne depend pas d'un seul canal. LinkedIn etablit la confiance, les medias locaux la legitimite, les recommandations accelerent le cycle de vente et le demarchage direct comble les ecarts.

Sheet Revenue_Model
A1: Modele de Revenus
A2: Calcul mensuel attendu. Permet de visualiser l'evolution dans le temps de la capacite de facturation.
A4: Indicateur | B4: 2026-06 | C4: 2026-07 | D4: 2026-08 | E4: 2026-09 | F4: 2026-10 | G4: 2026-11 | H4: 2026-12 | I4: 2027-01 | J4: 2027-02 | K4: 2027-03 | L4: 2027-04 | M4: 2027-05 | N4: 2027-06 | O4: 2027-07 | P4: 2027-08 | Q4: 2027-09 | R4: 2027-10 | S4: 2027-11 | T4: 2027-12 | U4: 2028-01 | V4: 2028-02 | W4: 2028-03 | X4: 2028-04 | Y4: 2028-05 | Z4: 2028-06 | AA4: 2028-07 | AB4: 2028-08 | AC4: 2028-09 | AD4: 2028-10 | AE4: 2028-11 | AF4: 2028-12 | AG4: 2029-01 | AH4: 2029-02 | AI4: 2029-03 | AJ4: 2029-04 | AK4: 2029-05
B5: 1 | C5: 2 | D5: 3 | E5: 4 | F5: 5 | G5: 6 | H5: 7 | I5: 8 | J5: 9 | K5: 10 | L5: 11 | M5: 12 | N5: 13 | O5: 14 | P5: 15 | Q5: 16 | R5: 17 | S5: 18 | T5: 19 | U5: 20 | V5: 21 | W5: 22 | X5: 23 | Y5: 24 | Z5: 25 | AA5: 26 | AB5: 27 | AC5: 28 | AD5: 29 | AE5: 30 | AF5: 31 | AG5: 32 | AH5: 33 | AI5: 34 | AJ5: 35 | AK5: 36
A7: Audit / Diagnostic (Unites) | B7: =MIN(Assumptions!$D$25,Assumptions!$B$25+((2-2)*Assumptions!$C$25)) | C7: =MIN(Assumptions!$D$25,Assumptions!$B$25+((3-2)*Assumptions!$C$25)) | D7: =MIN(Assumptions!$D$25,Assumptions!$B$25+((4-2)*Assumptions!$C$25)) | E7: =MIN(Assumptions!$D$25,Assumptions!$B$25+((5-2)*Assumptions!$C$25)) | F7: =MIN(Assumptions!$D$25,Assumptions!$B$25+((6-2)*Assumptions!$C$25)) | G7: =MIN(Assumptions!$D$25,Assumptions!$B$25+((7-2)*Assumptions!$C$25)) | H7: =MIN(Assumptions!$D$25,Assumptions!$B$25+((8-2)*Assumptions!$C$25)) | I7: =MIN(Assumptions!$D$25,Assumptions!$B$25+((9-2)*Assumptions!$C$25)) | J7: =MIN(Assumptions!$D$25,Assumptions!$B$25+((10-2)*Assumptions!$C$25)) | K7: =MIN(Assumptions!$D$25,Assumptions!$B$25+((11-2)*Assumptions!$C$25)) | L7: =MIN(Assumptions!$D$25,Assumptions!$B$25+((12-2)*Assumptions!$C$25)) | M7: =MIN(Assumptions!$D$25,Assumptions!$B$25+((13-2)*Assumptions!$C$25)) | N7: =MIN(Assumptions!$D$25,Assumptions!$B$25+((14-2)*Assumptions!$C$25)) | O7: =MIN(Assumptions!$D$25,Assumptions!$B$25+((15-2)*Assumptions!$C$25)) | P7: =MIN(Assumptions!$D$25,Assumptions!$B$25+((16-2)*Assumptions!$C$25)) | Q7: =MIN(Assumptions!$D$25,Assumptions!$B$25+((17-2)*Assumptions!$C$25)) | R7: =MIN(Assumptions!$D$25,Assumptions!$B$25+((18-2)*Assumptions!$C$25)) | S7: =MIN(Assumptions!$D$25,Assumptions!$B$25+((19-2)*Assumptions!$C$25)) | T7: =MIN(Assumptions!$D$25,Assumptions!$B$25+((20-2)*Assumptions!$C$25)) | U7: =MIN(Assumptions!$D$25,Assumptions!$B$25+((21-2)*Assumptions!$C$25)) | V7: =MIN(Assumptions!$D$25,Assumptions!$B$25+((22-2)*Assumptions!$C$25)) | W7: =MIN(Assumptions!$D$25,Assumptions!$B$25+((23-2)*Assumptions!$C$25)) | X7: =MIN(Assumptions!$D$25,Assumptions!$B$25+((24-2)*Assumptions!$C$25)) | Y7: =MIN(Assumptions!$D$25,Assumptions!$B$25+((25-2)*Assumptions!$C$25)) | Z7: =MIN(Assumptions!$D$25,Assumptions!$B$25+((26-2)*Assumptions!$C$25)) | AA7: =MIN(Assumptions!$D$25,Assumptions!$B$25+((27-2)*Assumptions!$C$25)) | AB7: =MIN(Assumptions!$D$25,Assumptions!$B$25+((28-2)*Assumptions!$C$25)) | AC7: =MIN(Assumptions!$D$25,Assumptions!$B$25+((29-2)*Assumptions!$C$25)) | AD7: =MIN(Assumptions!$D$25,Assumptions!$B$25+((30-2)*Assumptions!$C$25)) | AE7: =MIN(Assumptions!$D$25,Assumptions!$B$25+((31-2)*Assumptions!$C$25)) | AF7: =MIN(Assumptions!$D$25,Assumptions!$B$25+((32-2)*Assumptions!$C$25)) | AG7: =MIN(Assumptions!$D$25,Assumptions!$B$25+((33-2)*Assumptions!$C$25)) | AH7: =MIN(Assumptions!$D$25,Assumptions!$B$25+((34-2)*Assumptions!$C$25)) | AI7: =MIN(Assumptions!$D$25,Assumptions!$B$25+((35-2)*Assumptions!$C$25)) | AJ7: =MIN(Assumptions!$D$25,Assumptions!$B$25+((36-2)*Assumptions!$C$25)) | AK7: =MIN(Assumptions!$D$25,Assumptions!$B$25+((37-2)*Assumptions!$C$25))
A8: Sprint d'Efficience (Unites) | B8: =MIN(Assumptions!$D$26,Assumptions!$B$26+((2-2)*Assumptions!$C$26)) | C8: =MIN(Assumptions!$D$26,Assumptions!$B$26+((3-2)*Assumptions!$C$26)) | D8: =MIN(Assumptions!$D$26,Assumptions!$B$26+((4-2)*Assumptions!$C$26)) | E8: =MIN(Assumptions!$D$26,Assumptions!$B$26+((5-2)*Assumptions!$C$26)) | F8: =MIN(Assumptions!$D$26,Assumptions!$B$26+((6-2)*Assumptions!$C$26)) | G8: =MIN(Assumptions!$D$26,Assumptions!$B$26+((7-2)*Assumptions!$C$26)) | H8: =MIN(Assumptions!$D$26,Assumptions!$B$26+((8-2)*Assumptions!$C$26)) | I8: =MIN(Assumptions!$D$26,Assumptions!$B$26+((9-2)*Assumptions!$C$26)) | J8: =MIN(Assumptions!$D$26,Assumptions!$B$26+((10-2)*Assumptions!$C$26)) | K8: =MIN(Assumptions!$D$26,Assumptions!$B$26+((11-2)*Assumptions!$C$26)) | L8: =MIN(Assumptions!$D$26,Assumptions!$B$26+((12-2)*Assumptions!$C$26)) | M8: =MIN(Assumptions!$D$26,Assumptions!$B$26+((13-2)*Assumptions!$C$26)) | N8: =MIN(Assumptions!$D$26,Assumptions!$B$26+((14-2)*Assumptions!$C$26)) | O8: =MIN(Assumptions!$D$26,Assumptions!$B$26+((15-2)*Assumptions!$C$26)) | P8: =MIN(Assumptions!$D$26,Assumptions!$B$26+((16-2)*Assumptions!$C$26)) | Q8: =MIN(Assumptions!$D$26,Assumptions!$B$26+((17-2)*Assumptions!$C$26)) | R8: =MIN(Assumptions!$D$26,Assumptions!$B$26+((18-2)*Assumptions!$C$26)) | S8: =MIN(Assumptions!$D$26,Assumptions!$B$26+((19-2)*Assumptions!$C$26)) | T8: =MIN(Assumptions!$D$26,Assumptions!$B$26+((20-2)*Assumptions!$C$26)) | U8: =MIN(Assumptions!$D$26,Assumptions!$B$26+((21-2)*Assumptions!$C$26)) | V8: =MIN(Assumptions!$D$26,Assumptions!$B$26+((22-2)*Assumptions!$C$26)) | W8: =MIN(Assumptions!$D$26,Assumptions!$B$26+((23-2)*Assumptions!$C$26)) | X8: =MIN(Assumptions!$D$26,Assumptions!$B$26+((24-2)*Assumptions!$C$26)) | Y8: =MIN(Assumptions!$D$26,Assumptions!$B$26+((25-2)*Assumptions!$C$26)) | Z8: =MIN(Assumptions!$D$26,Assumptions!$B$26+((26-2)*Assumptions!$C$26)) | AA8: =MIN(Assumptions!$D$26,Assumptions!$B$26+((27-2)*Assumptions!$C$26)) | AB8: =MIN(Assumptions!$D$26,Assumptions!$B$26+((28-2)*Assumptions!$C$26)) | AC8: =MIN(Assumptions!$D$26,Assumptions!$B$26+((29-2)*Assumptions!$C$26)) | AD8: =MIN(Assumptions!$D$26,Assumptions!$B$26+((30-2)*Assumptions!$C$26)) | AE8: =MIN(Assumptions!$D$26,Assumptions!$B$26+((31-2)*Assumptions!$C$26)) | AF8: =MIN(Assumptions!$D$26,Assumptions!$B$26+((32-2)*Assumptions!$C$26)) | AG8: =MIN(Assumptions!$D$26,Assumptions!$B$26+((33-2)*Assumptions!$C$26)) | AH8: =MIN(Assumptions!$D$26,Assumptions!$B$26+((34-2)*Assumptions!$C$26)) | AI8: =MIN(Assumptions!$D$26,Assumptions!$B$26+((35-2)*Assumptions!$C$26)) | AJ8: =MIN(Assumptions!$D$26,Assumptions!$B$26+((36-2)*Assumptions!$C$26)) | AK8: =MIN(Assumptions!$D$26,Assumptions!$B$26+((37-2)*Assumptions!$C$26))
A9: Projet d'Implementation (Unites) | B9: =MIN(Assumptions!$D$27,Assumptions!$B$27+((2-2)*Assumptions!$C$27)) | C9: =MIN(Assumptions!$D$27,Assumptions!$B$27+((3-2)*Assumptions!$C$27)) | D9: =MIN(Assumptions!$D$27,Assumptions!$B$27+((4-2)*Assumptions!$C$27)) | E9: =MIN(Assumptions!$D$27,Assumptions!$B$27+((5-2)*Assumptions!$C$27)) | F9: =MIN(Assumptions!$D$27,Assumptions!$B$27+((6-2)*Assumptions!$C$27)) | G9: =MIN(Assumptions!$D$27,Assumptions!$B$27+((7-2)*Assumptions!$C$27)) | H9: =MIN(Assumptions!$D$27,Assumptions!$B$27+((8-2)*Assumptions!$C$27)) | I9: =MIN(Assumptions!$D$27,Assumptions!$B$27+((9-2)*Assumptions!$C$27)) | J9: =MIN(Assumptions!$D$27,Assumptions!$B$27+((10-2)*Assumptions!$C$27)) | K9: =MIN(Assumptions!$D$27,Assumptions!$B$27+((11-2)*Assumptions!$C$27)) | L9: =MIN(Assumptions!$D$27,Assumptions!$B$27+((12-2)*Assumptions!$C$27)) | M9: =MIN(Assumptions!$D$27,Assumptions!$B$27+((13-2)*Assumptions!$C$27)) | N9: =MIN(Assumptions!$D$27,Assumptions!$B$27+((14-2)*Assumptions!$C$27)) | O9: =MIN(Assumptions!$D$27,Assumptions!$B$27+((15-2)*Assumptions!$C$27)) | P9: =MIN(Assumptions!$D$27,Assumptions!$B$27+((16-2)*Assumptions!$C$27)) | Q9: =MIN(Assumptions!$D$27,Assumptions!$B$27+((17-2)*Assumptions!$C$27)) | R9: =MIN(Assumptions!$D$27,Assumptions!$B$27+((18-2)*Assumptions!$C$27)) | S9: =MIN(Assumptions!$D$27,Assumptions!$B$27+((19-2)*Assumptions!$C$27)) | T9: =MIN(Assumptions!$D$27,Assumptions!$B$27+((20-2)*Assumptions!$C$27)) | U9: =MIN(Assumptions!$D$27,Assumptions!$B$27+((21-2)*Assumptions!$C$27)) | V9: =MIN(Assumptions!$D$27,Assumptions!$B$27+((22-2)*Assumptions!$C$27)) | W9: =MIN(Assumptions!$D$27,Assumptions!$B$27+((23-2)*Assumptions!$C$27)) | X9: =MIN(Assumptions!$D$27,Assumptions!$B$27+((24-2)*Assumptions!$C$27)) | Y9: =MIN(Assumptions!$D$27,Assumptions!$B$27+((25-2)*Assumptions!$C$27)) | Z9: =MIN(Assumptions!$D$27,Assumptions!$B$27+((26-2)*Assumptions!$C$27)) | AA9: =MIN(Assumptions!$D$27,Assumptions!$B$27+((27-2)*Assumptions!$C$27)) | AB9: =MIN(Assumptions!$D$27,Assumptions!$B$27+((28-2)*Assumptions!$C$27)) | AC9: =MIN(Assumptions!$D$27,Assumptions!$B$27+((29-2)*Assumptions!$C$27)) | AD9: =MIN(Assumptions!$D$27,Assumptions!$B$27+((30-2)*Assumptions!$C$27)) | AE9: =MIN(Assumptions!$D$27,Assumptions!$B$27+((31-2)*Assumptions!$C$27)) | AF9: =MIN(Assumptions!$D$27,Assumptions!$B$27+((32-2)*Assumptions!$C$27)) | AG9: =MIN(Assumptions!$D$27,Assumptions!$B$27+((33-2)*Assumptions!$C$27)) | AH9: =MIN(Assumptions!$D$27,Assumptions!$B$27+((34-2)*Assumptions!$C$27)) | AI9: =MIN(Assumptions!$D$27,Assumptions!$B$27+((35-2)*Assumptions!$C$27)) | AJ9: =MIN(Assumptions!$D$27,Assumptions!$B$27+((36-2)*Assumptions!$C$27)) | AK9: =MIN(Assumptions!$D$27,Assumptions!$B$27+((37-2)*Assumptions!$C$27))
A10: Forge Retainer (Accompagnement) (Unites) | B10: =MIN(Assumptions!$D$28,Assumptions!$B$28+((2-2)*Assumptions!$C$28)) | C10: =MIN(Assumptions!$D$28,Assumptions!$B$28+((3-2)*Assumptions!$C$28)) | D10: =MIN(Assumptions!$D$28,Assumptions!$B$28+((4-2)*Assumptions!$C$28)) | E10: =MIN(Assumptions!$D$28,Assumptions!$B$28+((5-2)*Assumptions!$C$28)) | F10: =MIN(Assumptions!$D$28,Assumptions!$B$28+((6-2)*Assumptions!$C$28)) | G10: =MIN(Assumptions!$D$28,Assumptions!$B$28+((7-2)*Assumptions!$C$28)) | H10: =MIN(Assumptions!$D$28,Assumptions!$B$28+((8-2)*Assumptions!$C$28)) | I10: =MIN(Assumptions!$D$28,Assumptions!$B$28+((9-2)*Assumptions!$C$28)) | J10: =MIN(Assumptions!$D$28,Assumptions!$B$28+((10-2)*Assumptions!$C$28)) | K10: =MIN(Assumptions!$D$28,Assumptions!$B$28+((11-2)*Assumptions!$C$28)) | L10: =MIN(Assumptions!$D$28,Assumptions!$B$28+((12-2)*Assumptions!$C$28)) | M10: =MIN(Assumptions!$D$28,Assumptions!$B$28+((13-2)*Assumptions!$C$28)) | N10: =MIN(Assumptions!$D$28,Assumptions!$B$28+((14-2)*Assumptions!$C$28)) | O10: =MIN(Assumptions!$D$28,Assumptions!$B$28+((15-2)*Assumptions!$C$28)) | P10: =MIN(Assumptions!$D$28,Assumptions!$B$28+((16-2)*Assumptions!$C$28)) | Q10: =MIN(Assumptions!$D$28,Assumptions!$B$28+((17-2)*Assumptions!$C$28)) | R10: =MIN(Assumptions!$D$28,Assumptions!$B$28+((18-2)*Assumptions!$C$28)) | S10: =MIN(Assumptions!$D$28,Assumptions!$B$28+((19-2)*Assumptions!$C$28)) | T10: =MIN(Assumptions!$D$28,Assumptions!$B$28+((20-2)*Assumptions!$C$28)) | U10: =MIN(Assumptions!$D$28,Assumptions!$B$28+((21-2)*Assumptions!$C$28)) | V10: =MIN(Assumptions!$D$28,Assumptions!$B$28+((22-2)*Assumptions!$C$28)) | W10: =MIN(Assumptions!$D$28,Assumptions!$B$28+((23-2)*Assumptions!$C$28)) | X10: =MIN(Assumptions!$D$28,Assumptions!$B$28+((24-2)*Assumptions!$C$28)) | Y10: =MIN(Assumptions!$D$28,Assumptions!$B$28+((25-2)*Assumptions!$C$28)) | Z10: =MIN(Assumptions!$D$28,Assumptions!$B$28+((26-2)*Assumptions!$C$28)) | AA10: =MIN(Assumptions!$D$28,Assumptions!$B$28+((27-2)*Assumptions!$C$28)) | AB10: =MIN(Assumptions!$D$28,Assumptions!$B$28+((28-2)*Assumptions!$C$28)) | AC10: =MIN(Assumptions!$D$28,Assumptions!$B$28+((29-2)*Assumptions!$C$28)) | AD10: =MIN(Assumptions!$D$28,Assumptions!$B$28+((30-2)*Assumptions!$C$28)) | AE10: =MIN(Assumptions!$D$28,Assumptions!$B$28+((31-2)*Assumptions!$C$28)) | AF10: =MIN(Assumptions!$D$28,Assumptions!$B$28+((32-2)*Assumptions!$C$28)) | AG10: =MIN(Assumptions!$D$28,Assumptions!$B$28+((33-2)*Assumptions!$C$28)) | AH10: =MIN(Assumptions!$D$28,Assumptions!$B$28+((34-2)*Assumptions!$C$28)) | AI10: =MIN(Assumptions!$D$28,Assumptions!$B$28+((35-2)*Assumptions!$C$28)) | AJ10: =MIN(Assumptions!$D$28,Assumptions!$B$28+((36-2)*Assumptions!$C$28)) | AK10: =MIN(Assumptions!$D$28,Assumptions!$B$28+((37-2)*Assumptions!$C$28))
A11: Sovereign Retainer (R&D) (Unites) | B11: =MIN(Assumptions!$D$29,Assumptions!$B$29+((2-2)*Assumptions!$C$29)) | C11: =MIN(Assumptions!$D$29,Assumptions!$B$29+((3-2)*Assumptions!$C$29)) | D11: =MIN(Assumptions!$D$29,Assumptions!$B$29+((4-2)*Assumptions!$C$29)) | E11: =MIN(Assumptions!$D$29,Assumptions!$B$29+((5-2)*Assumptions!$C$29)) | F11: =MIN(Assumptions!$D$29,Assumptions!$B$29+((6-2)*Assumptions!$C$29)) | G11: =MIN(Assumptions!$D$29,Assumptions!$B$29+((7-2)*Assumptions!$C$29)) | H11: =MIN(Assumptions!$D$29,Assumptions!$B$29+((8-2)*Assumptions!$C$29)) | I11: =MIN(Assumptions!$D$29,Assumptions!$B$29+((9-2)*Assumptions!$C$29)) | J11: =MIN(Assumptions!$D$29,Assumptions!$B$29+((10-2)*Assumptions!$C$29)) | K11: =MIN(Assumptions!$D$29,Assumptions!$B$29+((11-2)*Assumptions!$C$29)) | L11: =MIN(Assumptions!$D$29,Assumptions!$B$29+((12-2)*Assumptions!$C$29)) | M11: =MIN(Assumptions!$D$29,Assumptions!$B$29+((13-2)*Assumptions!$C$29)) | N11: =MIN(Assumptions!$D$29,Assumptions!$B$29+((14-2)*Assumptions!$C$29)) | O11: =MIN(Assumptions!$D$29,Assumptions!$B$29+((15-2)*Assumptions!$C$29)) | P11: =MIN(Assumptions!$D$29,Assumptions!$B$29+((16-2)*Assumptions!$C$29)) | Q11: =MIN(Assumptions!$D$29,Assumptions!$B$29+((17-2)*Assumptions!$C$29)) | R11: =MIN(Assumptions!$D$29,Assumptions!$B$29+((18-2)*Assumptions!$C$29)) | S11: =MIN(Assumptions!$D$29,Assumptions!$B$29+((19-2)*Assumptions!$C$29)) | T11: =MIN(Assumptions!$D$29,Assumptions!$B$29+((20-2)*Assumptions!$C$29)) | U11: =MIN(Assumptions!$D$29,Assumptions!$B$29+((21-2)*Assumptions!$C$29)) | V11: =MIN(Assumptions!$D$29,Assumptions!$B$29+((22-2)*Assumptions!$C$29)) | W11: =MIN(Assumptions!$D$29,Assumptions!$B$29+((23-2)*Assumptions!$C$29)) | X11: =MIN(Assumptions!$D$29,Assumptions!$B$29+((24-2)*Assumptions!$C$29)) | Y11: =MIN(Assumptions!$D$29,Assumptions!$B$29+((25-2)*Assumptions!$C$29)) | Z11: =MIN(Assumptions!$D$29,Assumptions!$B$29+((26-2)*Assumptions!$C$29)) | AA11: =MIN(Assumptions!$D$29,Assumptions!$B$29+((27-2)*Assumptions!$C$29)) | AB11: =MIN(Assumptions!$D$29,Assumptions!$B$29+((28-2)*Assumptions!$C$29)) | AC11: =MIN(Assumptions!$D$29,Assumptions!$B$29+((29-2)*Assumptions!$C$29)) | AD11: =MIN(Assumptions!$D$29,Assumptions!$B$29+((30-2)*Assumptions!$C$29)) | AE11: =MIN(Assumptions!$D$29,Assumptions!$B$29+((31-2)*Assumptions!$C$29)) | AF11: =MIN(Assumptions!$D$29,Assumptions!$B$29+((32-2)*Assumptions!$C$29)) | AG11: =MIN(Assumptions!$D$29,Assumptions!$B$29+((33-2)*Assumptions!$C$29)) | AH11: =MIN(Assumptions!$D$29,Assumptions!$B$29+((34-2)*Assumptions!$C$29)) | AI11: =MIN(Assumptions!$D$29,Assumptions!$B$29+((35-2)*Assumptions!$C$29)) | AJ11: =MIN(Assumptions!$D$29,Assumptions!$B$29+((36-2)*Assumptions!$C$29)) | AK11: =MIN(Assumptions!$D$29,Assumptions!$B$29+((37-2)*Assumptions!$C$29))
A12: Dossier Sovereign (Unites) | B12: =MIN(Assumptions!$D$30,Assumptions!$B$30+((2-2)*Assumptions!$C$30)) | C12: =MIN(Assumptions!$D$30,Assumptions!$B$30+((3-2)*Assumptions!$C$30)) | D12: =MIN(Assumptions!$D$30,Assumptions!$B$30+((4-2)*Assumptions!$C$30)) | E12: =MIN(Assumptions!$D$30,Assumptions!$B$30+((5-2)*Assumptions!$C$30)) | F12: =MIN(Assumptions!$D$30,Assumptions!$B$30+((6-2)*Assumptions!$C$30)) | G12: =MIN(Assumptions!$D$30,Assumptions!$B$30+((7-2)*Assumptions!$C$30)) | H12: =MIN(Assumptions!$D$30,Assumptions!$B$30+((8-2)*Assumptions!$C$30)) | I12: =MIN(Assumptions!$D$30,Assumptions!$B$30+((9-2)*Assumptions!$C$30)) | J12: =MIN(Assumptions!$D$30,Assumptions!$B$30+((10-2)*Assumptions!$C$30)) | K12: =MIN(Assumptions!$D$30,Assumptions!$B$30+((11-2)*Assumptions!$C$30)) | L12: =MIN(Assumptions!$D$30,Assumptions!$B$30+((12-2)*Assumptions!$C$30)) | M12: =MIN(Assumptions!$D$30,Assumptions!$B$30+((13-2)*Assumptions!$C$30)) | N12: =MIN(Assumptions!$D$30,Assumptions!$B$30+((14-2)*Assumptions!$C$30)) | O12: =MIN(Assumptions!$D$30,Assumptions!$B$30+((15-2)*Assumptions!$C$30)) | P12: =MIN(Assumptions!$D$30,Assumptions!$B$30+((16-2)*Assumptions!$C$30)) | Q12: =MIN(Assumptions!$D$30,Assumptions!$B$30+((17-2)*Assumptions!$C$30)) | R12: =MIN(Assumptions!$D$30,Assumptions!$B$30+((18-2)*Assumptions!$C$30)) | S12: =MIN(Assumptions!$D$30,Assumptions!$B$30+((19-2)*Assumptions!$C$30)) | T12: =MIN(Assumptions!$D$30,Assumptions!$B$30+((20-2)*Assumptions!$C$30)) | U12: =MIN(Assumptions!$D$30,Assumptions!$B$30+((21-2)*Assumptions!$C$30)) | V12: =MIN(Assumptions!$D$30,Assumptions!$B$30+((22-2)*Assumptions!$C$30)) | W12: =MIN(Assumptions!$D$30,Assumptions!$B$30+((23-2)*Assumptions!$C$30)) | X12: =MIN(Assumptions!$D$30,Assumptions!$B$30+((24-2)*Assumptions!$C$30)) | Y12: =MIN(Assumptions!$D$30,Assumptions!$B$30+((25-2)*Assumptions!$C$30)) | Z12: =MIN(Assumptions!$D$30,Assumptions!$B$30+((26-2)*Assumptions!$C$30)) | AA12: =MIN(Assumptions!$D$30,Assumptions!$B$30+((27-2)*Assumptions!$C$30)) | AB12: =MIN(Assumptions!$D$30,Assumptions!$B$30+((28-2)*Assumptions!$C$30)) | AC12: =MIN(Assumptions!$D$30,Assumptions!$B$30+((29-2)*Assumptions!$C$30)) | AD12: =MIN(Assumptions!$D$30,Assumptions!$B$30+((30-2)*Assumptions!$C$30)) | AE12: =MIN(Assumptions!$D$30,Assumptions!$B$30+((31-2)*Assumptions!$C$30)) | AF12: =MIN(Assumptions!$D$30,Assumptions!$B$30+((32-2)*Assumptions!$C$30)) | AG12: =MIN(Assumptions!$D$30,Assumptions!$B$30+((33-2)*Assumptions!$C$30)) | AH12: =MIN(Assumptions!$D$30,Assumptions!$B$30+((34-2)*Assumptions!$C$30)) | AI12: =MIN(Assumptions!$D$30,Assumptions!$B$30+((35-2)*Assumptions!$C$30)) | AJ12: =MIN(Assumptions!$D$30,Assumptions!$B$30+((36-2)*Assumptions!$C$30)) | AK12: =MIN(Assumptions!$D$30,Assumptions!$B$30+((37-2)*Assumptions!$C$30))
A15: Audit / Diagnostic (CA) | B15: =B7*Assumptions!$B$15 | C15: =C7*Assumptions!$B$15 | D15: =D7*Assumptions!$B$15 | E15: =E7*Assumptions!$B$15 | F15: =F7*Assumptions!$B$15 | G15: =G7*Assumptions!$B$15 | H15: =H7*Assumptions!$B$15 | I15: =I7*Assumptions!$B$15 | ... AK15: =AK7*Assumptions!$B$15
A16: Sprint d'Efficience (CA) | B16: =B8*Assumptions!$B$16 | C16: =C8*Assumptions!$B$16 | D16: =D8*Assumptions!$B$16 | E16: =E8*Assumptions!$B$16 | F16: =F8*Assumptions!$B$16 | G16: =G8*Assumptions!$B$16 | H16: =H8*Assumptions!$B$16 | I16: =I8*Assumptions!$B$16 | ... AK16: =AK8*Assumptions!$B$16
A17: Projet d'Implementation (CA) | B17: =B9*Assumptions!$B$17 | C17: =C9*Assumptions!$B$17 | D17: =D9*Assumptions!$B$17 | E17: =E9*Assumptions!$B$17 | F17: =F9*Assumptions!$B$17 | G17: =G9*Assumptions!$B$17 | H17: =H9*Assumptions!$B$17 | I17: =I9*Assumptions!$B$17 | ... AK17: =AK9*Assumptions!$B$17
A18: Forge Retainer (Accompagnement) (CA) | B18: =B10*Assumptions!$B$18 | C18: =C10*Assumptions!$B$18 | D18: =D10*Assumptions!$B$18 | E18: =E10*Assumptions!$B$18 | F18: =F10*Assumptions!$B$18 | G18: =G10*Assumptions!$B$18 | H18: =H10*Assumptions!$B$18 | I18: =I10*Assumptions!$B$18 | ... AK18: =AK10*Assumptions!$B$18
A19: Sovereign Retainer (R&D) (CA) | B19: =B11*Assumptions!$B$19 | C19: =C11*Assumptions!$B$19 | D19: =D11*Assumptions!$B$19 | E19: =E11*Assumptions!$B$19 | F19: =F11*Assumptions!$B$19 | G19: =G11*Assumptions!$B$19 | H19: =H11*Assumptions!$B$19 | I19: =I11*Assumptions!$B$19 | ... AK19: =AK11*Assumptions!$B$19
A20: Dossier Sovereign (CA) | B20: =B12*Assumptions!$B$20 | C20: =C12*Assumptions!$B$20 | D20: =D12*Assumptions!$B$20 | E20: =E12*Assumptions!$B$20 | F20: =F12*Assumptions!$B$20 | G20: =G12*Assumptions!$B$20 | H20: =H12*Assumptions!$B$20 | I20: =I12*Assumptions!$B$20 | ... AK20: =AK12*Assumptions!$B$20
A23: Audit / Diagnostic (Cout direct) | B23: =B15*Assumptions!$C$15 | C23: =C15*Assumptions!$C$15 | D23: =D15*Assumptions!$C$15 | E23: =E15*Assumptions!$C$15 | F23: =F15*Assumptions!$C$15 | G23: =G15*Assumptions!$C$15 | H23: =H15*Assumptions!$C$15 | I23: =I15*Assumptions!$C$15 | ... AK23: =AK15*Assumptions!$C$15
A24: Sprint d'Efficience (Cout direct) | B24: =B16*Assumptions!$C$16 | C24: =C16*Assumptions!$C$16 | D24: =D16*Assumptions!$C$16 | E24: =E16*Assumptions!$C$16 | F24: =F16*Assumptions!$C$16 | G24: =G16*Assumptions!$C$16 | H24: =H16*Assumptions!$C$16 | I24: =I16*Assumptions!$C$16 | ... AK24: =AK16*Assumptions!$C$16
A25: Projet d'Implementation (Cout direct) | B25: =B17*Assumptions!$C$17 | C25: =C17*Assumptions!$C$17 | D25: =D17*Assumptions!$C$17 | E25: =E17*Assumptions!$C$17 | F25: =F17*Assumptions!$C$17 | G25: =G17*Assumptions!$C$17 | H25: =H17*Assumptions!$C$17 | I25: =I17*Assumptions!$C$17 | ... AK25: =AK17*Assumptions!$C$17
A26: Forge Retainer (Accompagnement) (Cout direct) | B26: =B18*Assumptions!$C$18 | C26: =C18*Assumptions!$C$18 | D26: =D18*Assumptions!$C$18 | E26: =E18*Assumptions!$C$18 | F26: =F18*Assumptions!$C$18 | G26: =G18*Assumptions!$C$18 | H26: =H18*Assumptions!$C$18 | I26: =I18*Assumptions!$C$18 | ... AK26: =AK18*Assumptions!$C$18
A27: Sovereign Retainer (R&D) (Cout direct) | B27: =B19*Assumptions!$C$19 | C27: =C19*Assumptions!$C$19 | D27: =D19*Assumptions!$C$19 | E27: =E19*Assumptions!$C$19 | F27: =F19*Assumptions!$C$19 | G27: =G19*Assumptions!$C$19 | H27: =H19*Assumptions!$C$19 | I27: =I19*Assumptions!$C$19 | ... AK27: =AK19*Assumptions!$C$19
A28: Dossier Sovereign (Cout direct) | B28: =B20*Assumptions!$C$20 | C28: =C20*Assumptions!$C$20 | D28: =D20*Assumptions!$C$20 | E28: =E20*Assumptions!$C$20 | F28: =F20*Assumptions!$C$20 | G28: =G20*Assumptions!$C$20 | H28: =H20*Assumptions!$C$20 | I28: =I20*Assumptions!$C$20 | ... AK28: =AK20*Assumptions!$C$20
A32: Chiffre d'Affaires global | B32: =SUM(B15:B20) | C32: =SUM(C15:C20) | D32: =SUM(D15:D20) | E32: =SUM(E15:E20) | F32: =SUM(F15:F20) | G32: =SUM(G15:G20) | H32: =SUM(H15:H20) | I32: =SUM(I15:I20) | ... AK32: =SUM(AK15:AK20)
A33: Cout direct total | B33: =SUM(B23:B28) | C33: =SUM(C23:C28) | D33: =SUM(D23:D28) | E33: =SUM(E23:E28) | F33: =SUM(F23:F28) | G33: =SUM(G23:G28) | H33: =SUM(H23:H28) | I33: =SUM(I23:I28) | ... AK33: =SUM(AK23:AK28)
A34: Marge brute (Valeur) | B34: =B32-B33 | C34: =C32-C33 | D34: =D32-D33 | E34: =E32-E33 | F34: =F32-F33 | G34: =G32-G33 | H34: =H32-H33 | I34: =I32-I33 | ... AK34: =AK32-AK33
A35: Marge brute (%) | B35: =IFERROR(B34/B32,0) | C35: =IFERROR(C34/C32,0) | D35: =IFERROR(D34/D32,0) | E35: =IFERROR(E34/E32,0) | F35: =IFERROR(F34/F32,0) | G35: =IFERROR(G34/G32,0) | H35: =IFERROR(H34/H32,0) | I35: =IFERROR(I34/I32,0) | ... AK35: =IFERROR(AK34/AK32,0)

Sheet Expenses
A1: Charges de fonctionnement
A2: Details de l'Opex fixe par phase temporelle pour maintenir la discipline financiere.
A4: Categorie d'Opex | B4: Mois 1-12 | C4: Mois 13-24 | D4: Mois 25-36
A5: Remuneration Fondateur / CEO | B5: 30000 | C5: 33000 | D5: 36000
A6: Support Operations & Gestion | B6: 10000 | C6: 12000 | D6: 14000
A7: Marketing & Contenu | B7: 10000 | C7: 12000 | D7: 16000
A8: Outils SaaS & Logiciels | B8: 5000 | C8: 6000 | D8: 7000
A9: Deplacements & Livraison client | B9: 6000 | C9: 7000 | D9: 8000
A10: Frais Juridiques, Comptables & Conformite | B10: 4500 | C10: 5000 | D10: 6000
A11: Admin, Internet & Telecoms | B11: 3500 | C11: 4000 | D11: 4500
A12: Reserve Imprevus / Contingence | B12: 4000 | C12: 4000 | D12: 5000
A13: Reserve Recrutement / Croissance | B13: 5000 | C13: 15000 | D13: 22000
A15: Total charges fixes (Opex) | B15: =IF(COLUMN()-1<=12,Assumptions!$B$35,IF(COLUMN()-1<=24,Assumptions!$C$35,Assumptions!$D$35))+IF(COLUMN()-1<=12,Assumptions!$B$36,IF(COLUMN()-1<=24,Assumptions!$C$36,Assumptions!$D$36))+IF(COLUMN()-1<=12,Assumptions!$B$37,IF(COLUMN()-1<=24,Assumptions!$C$37,Assumptions!$D$37))+IF(COLUMN()-1<=12,Assumptions!$B$38,IF(COLUMN()-1<=24,Assumptions!$C$38,Assumptions!$D$38))+IF(COLUMN()-1<=12,Assumptions!$B$39,IF(COLUMN()-1<=24,Assumptions!$C$39,Assumptions!$D$39))+IF(COLUMN()-1<=12,Assumptions!$B$40,IF(COLUMN()-1<=24,Assumptions!$C$40,Assumptions!$D$40))+IF(COLUMN()-1<=12,Assumptions!$B$41,IF(COLUMN()-1<=24,Assumptions!$C$41,Assumptions!$D$41))+IF(COLUMN()-1<=12,Assumptions!$B$42,IF(COLUMN()-1<=24,Assumptions!$C$42,Assumptions!$D$42))+IF(COLUMN()-1<=12,Assumptions!$B$43,IF(COLUMN()-1<=24,Assumptions!$C$43,Assumptions!$D$43)) | C15: =IF(COLUMN()-1<=12,Assumptions!$B$35,IF(COLUMN()-1<=24,Assumptions!$C$35,Assumptions!$D$35))+IF(COLUMN()-1<=12,Assumptions!$B$36,IF(COLUMN()-1<=24,Assumptions!$C$36,Assumptions!$D$36))+IF(COLUMN()-1<=12,Assumptions!$B$37,IF(COLUMN()-1<=24,Assumptions!$C$37,Assumptions!$D$37))+IF(COLUMN()-1<=12,Assumptions!$B$38,IF(COLUMN()-1<=24,Assumptions!$C$38,Assumptions!$D$38))+IF(COLUMN()-1<=12,Assumptions!$B$39,IF(COLUMN()-1<=24,Assumptions!$C$39,Assumptions!$D$39))+IF(COLUMN()-1<=12,Assumptions!$B$40,IF(COLUMN()-1<=24,Assumptions!$C$40,Assumptions!$D$40))+IF(COLUMN()-1<=12,Assumptions!$B$41,IF(COLUMN()-1<=24,Assumptions!$C$41,Assumptions!$D$41))+IF(COLUMN()-1<=12,Assumptions!$B$42,IF(COLUMN()-1<=24,Assumptions!$C$42,Assumptions!$D$42))+IF(COLUMN()-1<=12,Assumptions!$B$43,IF(COLUMN()-1<=24,Assumptions!$C$43,Assumptions!$D$43)) | D15: =IF(COLUMN()-1<=12,Assumptions!$B$35,IF(COLUMN()-1<=24,Assumptions!$C$35,Assumptions!$D$35))+IF(COLUMN()-1<=12,Assumptions!$B$36,IF(COLUMN()-1<=24,Assumptions!$C$36,Assumptions!$D$36))+IF(COLUMN()-1<=12,Assumptions!$B$37,IF(COLUMN()-1<=24,Assumptions!$C$37,Assumptions!$D$37))+IF(COLUMN()-1<=12,Assumptions!$B$38,IF(COLUMN()-1<=24,Assumptions!$C$38,Assumptions!$D$38))+IF(COLUMN()-1<=12,Assumptions!$B$39,IF(COLUMN()-1<=24,Assumptions!$C$39,Assumptions!$D$39))+IF(COLUMN()-1<=12,Assumptions!$B$40,IF(COLUMN()-1<=24,Assumptions!$C$40,Assumptions!$D$40))+IF(COLUMN()-1<=12,Assumptions!$B$41,IF(COLUMN()-1<=24,Assumptions!$C$41,Assumptions!$D$41))+IF(COLUMN()-1<=12,Assumptions!$B$42,IF(COLUMN()-1<=24,Assumptions!$C$42,Assumptions!$D$42))+IF(COLUMN()-1<=12,Assumptions!$B$43,IF(COLUMN()-1<=24,Assumptions!$C$43,Assumptions!$D$43)) | E15: =IF(COLUMN()-1<=12,Assumptions!$B$35,IF(COLUMN()-1<=24,Assumptions!$C$35,Assumptions!$D$35))+IF(COLUMN()-1<=12,Assumptions!$B$36,IF(COLUMN()-1<=24,Assumptions!$C$36,Assumptions!$D$36))+IF(COLUMN()-1<=12,Assumptions!$B$37,IF(COLUMN()-1<=24,Assumptions!$C$37,Assumptions!$D$37))+IF(COLUMN()-1<=12,Assumptions!$B$38,IF(COLUMN()-1<=24,Assumptions!$C$38,Assumptions!$D$38))+IF(COLUMN()-1<=12,Assumptions!$B$39,IF(COLUMN()-1<=24,Assumptions!$C$39,Assumptions!$D$39))+IF(COLUMN()-1<=12,Assumptions!$B$40,IF(COLUMN()-1<=24,Assumptions!$C$40,Assumptions!$D$40))+IF(COLUMN()-1<=12,Assumptions!$B$41,IF(COLUMN()-1<=24,Assumptions!$C$41,Assumptions!$D$41))+IF(COLUMN()-1<=12,Assumptions!$B$42,IF(COLUMN()-1<=24,Assumptions!$C$42,Assumptions!$D$42))+IF(COLUMN()-1<=12,Assumptions!$B$43,IF(COLUMN()-1<=24,Assumptions!$C$43,Assumptions!$D$43)) | F15: =IF(COLUMN()-1<=12,Assumptions!$B$35,IF(COLUMN()-1<=24,Assumptions!$C$35,Assumptions!$D$35))+IF(COLUMN()-1<=12,Assumptions!$B$36,IF(COLUMN()-1<=24,Assumptions!$C$36,Assumptions!$D$36))+IF(COLUMN()-1<=12,Assumptions!$B$37,IF(COLUMN()-1<=24,Assumptions!$C$37,Assumptions!$D$37))+IF(COLUMN()-1<=12,Assumptions!$B$38,IF(COLUMN()-1<=24,Assumptions!$C$38,Assumptions!$D$38))+IF(COLUMN()-1<=12,Assumptions!$B$39,IF(COLUMN()-1<=24,Assumptions!$C$39,Assumptions!$D$39))+IF(COLUMN()-1<=12,Assumptions!$B$40,IF(COLUMN()-1<=24,Assumptions!$C$40,Assumptions!$D$40))+IF(COLUMN()-1<=12,Assumptions!$B$41,IF(COLUMN()-1<=24,Assumptions!$C$41,Assumptions!$D$41))+IF(COLUMN()-1<=12,Assumptions!$B$42,IF(COLUMN()-1<=24,Assumptions!$C$42,Assumptions!$D$42))+IF(COLUMN()-1<=12,Assumptions!$B$43,IF(COLUMN()-1<=24,Assumptions!$C$43,Assumptions!$D$43)) | G15: =IF(COLUMN()-1<=12,Assumptions!$B$35,IF(COLUMN()-1<=24,Assumptions!$C$35,Assumptions!$D$35))+IF(COLUMN()-1<=12,Assumptions!$B$36,IF(COLUMN()-1<=24,Assumptions!$C$36,Assumptions!$D$36))+IF(COLUMN()-1<=12,Assumptions!$B$37,IF(COLUMN()-1<=24,Assumptions!$C$37,Assumptions!$D$37))+IF(COLUMN()-1<=12,Assumptions!$B$38,IF(COLUMN()-1<=24,Assumptions!$C$38,Assumptions!$D$38))+IF(COLUMN()-1<=12,Assumptions!$B$39,IF(COLUMN()-1<=24,Assumptions!$C$39,Assumptions!$D$39))+IF(COLUMN()-1<=12,Assumptions!$B$40,IF(COLUMN()-1<=24,Assumptions!$C$40,Assumptions!$D$40))+IF(COLUMN()-1<=12,Assumptions!$B$41,IF(COLUMN()-1<=24,Assumptions!$C$41,Assumptions!$D$41))+IF(COLUMN()-1<=12,Assumptions!$B$42,IF(COLUMN()-1<=24,Assumptions!$C$42,Assumptions!$D$42))+IF(COLUMN()-1<=12,Assumptions!$B$43,IF(COLUMN()-1<=24,Assumptions!$C$43,Assumptions!$D$43)) | H15: =IF(COLUMN()-1<=12,Assumptions!$B$35,IF(COLUMN()-1<=24,Assumptions!$C$35,Assumptions!$D$35))+IF(COLUMN()-1<=12,Assumptions!$B$36,IF(COLUMN()-1<=24,Assumptions!$C$36,Assumptions!$D$36))+IF(COLUMN()-1<=12,Assumptions!$B$37,IF(COLUMN()-1<=24,Assumptions!$C$37,Assumptions!$D$37))+IF(COLUMN()-1<=12,Assumptions!$B$38,IF(COLUMN()-1<=24,Assumptions!$C$38,Assumptions!$D$38))+IF(COLUMN()-1<=12,Assumptions!$B$39,IF(COLUMN()-1<=24,Assumptions!$C$39,Assumptions!$D$39))+IF(COLUMN()-1<=12,Assumptions!$B$40,IF(COLUMN()-1<=24,Assumptions!$C$40,Assumptions!$D$40))+IF(COLUMN()-1<=12,Assumptions!$B$41,IF(COLUMN()-1<=24,Assumptions!$C$41,Assumptions!$D$41))+IF(COLUMN()-1<=12,Assumptions!$B$42,IF(COLUMN()-1<=24,Assumptions!$C$42,Assumptions!$D$42))+IF(COLUMN()-1<=12,Assumptions!$B$43,IF(COLUMN()-1<=24,Assumptions!$C$43,Assumptions!$D$43)) | I15: =IF(COLUMN()-1<=12,Assumptions!$B$35,IF(COLUMN()-1<=24,Assumptions!$C$35,Assumptions!$D$35))+IF(COLUMN()-1<=12,Assumptions!$B$36,IF(COLUMN()-1<=24,Assumptions!$C$36,Assumptions!$D$36))+IF(COLUMN()-1<=12,Assumptions!$B$37,IF(COLUMN()-1<=24,Assumptions!$C$37,Assumptions!$D$37))+IF(COLUMN()-1<=12,Assumptions!$B$38,IF(COLUMN()-1<=24,Assumptions!$C$38,Assumptions!$D$38))+IF(COLUMN()-1<=12,Assumptions!$B$39,IF(COLUMN()-1<=24,Assumptions!$C$39,Assumptions!$D$39))+IF(COLUMN()-1<=12,Assumptions!$B$40,IF(COLUMN()-1<=24,Assumptions!$C$40,Assumptions!$D$40))+IF(COLUMN()-1<=12,Assumptions!$B$41,IF(COLUMN()-1<=24,Assumptions!$C$41,Assumptions!$D$41))+IF(COLUMN()-1<=12,Assumptions!$B$42,IF(COLUMN()-1<=24,Assumptions!$C$42,Assumptions!$D$42))+IF(COLUMN()-1<=12,Assumptions!$B$43,IF(COLUMN()-1<=24,Assumptions!$C$43,Assumptions!$D$43)) | ... AK15: =IF(COLUMN()-1<=12,Assumptions!$B$35,IF(COLUMN()-1<=24,Assumptions!$C$35,Assumptions!$D$35))+IF(COLUMN()-1<=12,Assumptions!$B$36,IF(COLUMN()-1<=24,Assumptions!$C$36,Assumptions!$D$36))+IF(COLUMN()-1<=12,Assumptions!$B$37,IF(COLUMN()-1<=24,Assumptions!$C$37,Assumptions!$D$37))+IF(COLUMN()-1<=12,Assumptions!$B$38,IF(COLUMN()-1<=24,Assumptions!$C$38,Assumptions!$D$38))+IF(COLUMN()-1<=12,Assumptions!$B$39,IF(COLUMN()-1<=24,Assumptions!$C$39,Assumptions!$D$39))+IF(COLUMN()-1<=12,Assumptions!$B$40,IF(COLUMN()-1<=24,Assumptions!$C$40,Assumptions!$D$40))+IF(COLUMN()-1<=12,Assumptions!$B$41,IF(COLUMN()-1<=24,Assumptions!$C$41,Assumptions!$D$41))+IF(COLUMN()-1<=12,Assumptions!$B$42,IF(COLUMN()-1<=24,Assumptions!$C$42,Assumptions!$D$42))+IF(COLUMN()-1<=12,Assumptions!$B$43,IF(COLUMN()-1<=24,Assumptions!$C$43,Assumptions!$D$43))

Sheet P&L
A1: Compte de Resultat
A2: Vue previsionnelle mensuelle et synthese annuelle. Indispensable pour la credibilite du dossier.
B4: 2026-06 | C4: 2026-07 | D4: 2026-08 | E4: 2026-09 | F4: 2026-10 | G4: 2026-11 | H4: 2026-12 | I4: 2027-01 | J4: 2027-02 | K4: 2027-03 | L4: 2027-04 | M4: 2027-05 | N4: 2027-06 | O4: 2027-07 | P4: 2027-08 | Q4: 2027-09 | R4: 2027-10 | S4: 2027-11 | T4: 2027-12 | U4: 2028-01 | V4: 2028-02 | W4: 2028-03 | X4: 2028-04 | Y4: 2028-05 | Z4: 2028-06 | AA4: 2028-07 | AB4: 2028-08 | AC4: 2028-09 | AD4: 2028-10 | AE4: 2028-11 | AF4: 2028-12 | AG4: 2029-01 | AH4: 2029-02 | AI4: 2029-03 | AJ4: 2029-04 | AK4: 2029-05
A6: Chiffre d'Affaires | B6: ='Revenue_Model'!B32 | C6: ='Revenue_Model'!C32 | D6: ='Revenue_Model'!D32 | E6: ='Revenue_Model'!E32 | F6: ='Revenue_Model'!F32 | G6: ='Revenue_Model'!G32 | H6: ='Revenue_Model'!H32 | I6: ='Revenue_Model'!I32 | ... AK6: ='Revenue_Model'!AK32
A7: Cout direct | B7: ='Revenue_Model'!B33 | C7: ='Revenue_Model'!C33 | D7: ='Revenue_Model'!D33 | E7: ='Revenue_Model'!E33 | F7: ='Revenue_Model'!F33 | G7: ='Revenue_Model'!G33 | H7: ='Revenue_Model'!H33 | I7: ='Revenue_Model'!I33 | ... AK7: ='Revenue_Model'!AK33
A8: Marge brute | B8: ='Revenue_Model'!B34 | C8: ='Revenue_Model'!C34 | D8: ='Revenue_Model'!D34 | E8: ='Revenue_Model'!E34 | F8: ='Revenue_Model'!F34 | G8: ='Revenue_Model'!G34 | H8: ='Revenue_Model'!H34 | I8: ='Revenue_Model'!I34 | ... AK8: ='Revenue_Model'!AK34
A9: Marge brute % | B9: =IFERROR(B8/B6,0) | C9: =IFERROR(C8/C6,0) | D9: =IFERROR(D8/D6,0) | E9: =IFERROR(E8/E6,0) | F9: =IFERROR(F8/F6,0) | G9: =IFERROR(G8/G6,0) | H9: =IFERROR(H8/H6,0) | I9: =IFERROR(I8/I6,0) | ... AK9: =IFERROR(AK8/AK6,0)
A10: Frais de fonctionnement (Opex) | B10: ='Expenses'!B15 | C10: ='Expenses'!C15 | D10: ='Expenses'!D15 | E10: ='Expenses'!E15 | F10: ='Expenses'!F15 | G10: ='Expenses'!G15 | H10: ='Expenses'!H15 | I10: ='Expenses'!I15 | ... AK10: ='Expenses'!AK15
A11: EBITDA | B11: =B8-B10 | C11: =C8-C10 | D11: =D8-D10 | E11: =E8-E10 | F11: =F8-F10 | G11: =G8-G10 | H11: =H8-H10 | I11: =I8-I10 | ... AK11: =AK8-AK10
A12: Impots (IS) | B12: =MAX(B11,0)*Assumptions!$B$8 | C12: =MAX(C11,0)*Assumptions!$B$8 | D12: =MAX(D11,0)*Assumptions!$B$8 | E12: =MAX(E11,0)*Assumptions!$B$8 | F12: =MAX(F11,0)*Assumptions!$B$8 | G12: =MAX(G11,0)*Assumptions!$B$8 | H12: =MAX(H11,0)*Assumptions!$B$8 | I12: =MAX(I11,0)*Assumptions!$B$8 | ... AK12: =MAX(AK11,0)*Assumptions!$B$8
A13: Resultat net | B13: =B11-B12 | C13: =C11-C12 | D13: =D11-D12 | E13: =E11-E12 | F13: =F11-F12 | G13: =G11-G12 | H13: =H11-H12 | I13: =I11-I12 | ... AK13: =AK11-AK12
A14: Marge EBITDA % | B14: =IFERROR(B11/B6,0) | C14: =IFERROR(C11/C6,0) | D14: =IFERROR(D11/D6,0) | E14: =IFERROR(E11/E6,0) | F14: =IFERROR(F11/F6,0) | G14: =IFERROR(G11/G6,0) | H14: =IFERROR(H11/H6,0) | I14: =IFERROR(I11/I6,0) | ... AK14: =IFERROR(AK11/AK6,0)
A17: Synthese annuelle | B17: Annee 1 | C17: Annee 2 | D17: Annee 3
A18: Chiffre d'Affaires | B18: =SUM('P&L'!B6:M6) | C18: =SUM('P&L'!N6:Y6) | D18: =SUM('P&L'!Z6:AK6)
A19: Marge brute | B19: =SUM('P&L'!B8:M8) | C19: =SUM('P&L'!N8:Y8) | D19: =SUM('P&L'!Z8:AK8)
A20: EBITDA | B20: =SUM('P&L'!B11:M11) | C20: =SUM('P&L'!N11:Y11) | D20: =SUM('P&L'!Z11:AK11)
A21: Resultat net | B21: =SUM('P&L'!B13:M13) | C21: =SUM('P&L'!N13:Y13) | D21: =SUM('P&L'!Z13:AK13)
A22: Tresorerie finale | B22: ='Cashflow'!M12 | C22: ='Cashflow'!Y12 | D22: ='Cashflow'!AK12

Sheet Cashflow
A1: Flux de Tresorerie
A2: Flux de tresorerie reels. C'est l'indicateur de securite et de survie que l'investisseur scrute apres les profits.
B4: 2026-06 | C4: 2026-07 | D4: 2026-08 | E4: 2026-09 | F4: 2026-10 | G4: 2026-11 | H4: 2026-12 | I4: 2027-01 | J4: 2027-02 | K4: 2027-03 | L4: 2027-04 | M4: 2027-05 | N4: 2027-06 | O4: 2027-07 | P4: 2027-08 | Q4: 2027-09 | R4: 2027-10 | S4: 2027-11 | T4: 2027-12 | U4: 2028-01 | V4: 2028-02 | W4: 2028-03 | X4: 2028-04 | Y4: 2028-05 | Z4: 2028-06 | AA4: 2028-07 | AB4: 2028-08 | AC4: 2028-09 | AD4: 2028-10 | AE4: 2028-11 | AF4: 2028-12 | AG4: 2029-01 | AH4: 2029-02 | AI4: 2029-03 | AJ4: 2029-04 | AK4: 2029-05
A6: Solde initial | B6: =Assumptions!$B$9 | C6: =B12 | D6: =C12 | E6: =D12 | F6: =E12 | G6: =F12 | H6: =G12 | I6: =H12 | J6: =I12 | ... AK6: =AJ12
A7: EBITDA | B7: ='P&L'!B11 | C7: ='P&L'!C11 | D7: ='P&L'!D11 | E7: ='P&L'!E11 | F7: ='P&L'!F11 | G7: ='P&L'!G11 | H7: ='P&L'!H11 | I7: ='P&L'!I11 | ... AK7: ='P&L'!AK11
A8: Impots payes | B8: ='P&L'!B12 | C8: ='P&L'!C12 | D8: ='P&L'!D12 | E8: ='P&L'!E12 | F8: ='P&L'!F12 | G8: ='P&L'!G12 | H8: ='P&L'!H12 | I8: ='P&L'!I12 | ... AK8: ='P&L'!AK12
A9: Investissements (Capex) | B9: =IF(B$4="2026-06",Assumptions!$B$11,IF(B$4="2027-06",20000,IF(B$4="2028-06",15000,0))) | C9: =IF(C$4="2026-06",Assumptions!$B$11,IF(C$4="2027-06",20000,IF(C$4="2028-06",15000,0))) | D9: =IF(D$4="2026-06",Assumptions!$B$11,IF(D$4="2027-06",20000,IF(D$4="2028-06",15000,0))) | E9: =IF(E$4="2026-06",Assumptions!$B$11,IF(E$4="2027-06",20000,IF(E$4="2028-06",15000,0))) | F9: =IF(F$4="2026-06",Assumptions!$B$11,IF(F$4="2027-06",20000,IF(F$4="2028-06",15000,0))) | G9: =IF(G$4="2026-06",Assumptions!$B$11,IF(G$4="2027-06",20000,IF(G$4="2028-06",15000,0))) | H9: =IF(H$4="2026-06",Assumptions!$B$11,IF(H$4="2027-06",20000,IF(H$4="2028-06",15000,0))) | I9: =IF(I$4="2026-06",Assumptions!$B$11,IF(I$4="2027-06",20000,IF(I$4="2028-06",15000,0))) | ... AK9: =IF(AK$4="2026-06",Assumptions!$B$11,IF(AK$4="2027-06",20000,IF(AK$4="2028-06",15000,0)))
A10: Apport financement | B10: 0 | C10: 0 | D10: 0 | E10: 0 | F10: 0 | G10: 0 | H10: 0 | I10: 0 | J10: 0 | K10: 0 | L10: 0 | M10: 0 | N10: 0 | O10: 0 | P10: 0 | Q10: 0 | R10: 0 | S10: 0 | T10: 0 | U10: 0 | V10: 0 | W10: 0 | X10: 0 | Y10: 0 | Z10: 0 | AA10: 0 | AB10: 0 | AC10: 0 | AD10: 0 | AE10: 0 | AF10: 0 | AG10: 0 | AH10: 0 | AI10: 0 | AJ10: 0 | AK10: 0
A11: Flux net de tresorerie | B11: =B7-B8-B9+B10 | C11: =C7-C8-C9+C10 | D11: =D7-D8-D9+D10 | E11: =E7-E8-E9+E10 | F11: =F7-F8-F9+F10 | G11: =G7-G8-G9+G10 | H11: =H7-H8-H9+H10 | I11: =I7-I8-I9+I10 | ... AK11: =AK7-AK8-AK9+AK10
A12: Solde final | B12: =B6+B11 | C12: =C6+C11 | D12: =D6+D11 | E12: =E6+E11 | F12: =F6+F11 | G12: =G6+G11 | H12: =H6+H11 | I12: =I6+I11 | ... AK12: =AK6+AK11

Sheet Funding
A1: Plan de Financement
A2: Deux visions : developpement commando (autofinance) et developpement accelere (levée de fonds).
A4: Poste | B4: Montant / Part | C4: Remarques
A5: Besoin minimum (Runway lean) | B5: 300000 | C5: Suffisant si pilote par le fondateur et livraison stricte.
A6: Financement recommande (Seed) | B6: 1200000 | C6: Capital d'acceleration : force commerciale, experts, IP et reserve.
A7: Affectation : Ventes & Image de marque | B7: 0.25 | C7: Creation de contenu, visibilite, acquisition et conversion.
A8: Affectation : Capacite de livraison | B8: 0.3 | C8: Sous-traitants, support technique et vitesse d'execution.
A9: Affectation : Standardisation & IP | B9: 0.2 | C9: Modeles d'agents, outils internes, capitalisation et architecture.
A10: Affectation : Conformite & Administration | B10: 0.1 | C10: Fiscalite locale, contrats, structure et standards juridiques.
A11: Affectation : Reserve de roulement | B11: 0.15 | C11: Securiser l'entreprise face aux delais de paiement.
A14: Note stratégique | B14: L'entreprise n'a pas besoin de fonds demesures pour exister. La levee de fonds sert uniquement a accelerer la commercialisation et a proteger le temps du fondateur pour fiabiliser la livraison.

Sheet Scenarios
A1: Analyse des Scenarios
A2: Scénarios conservateurs, de base et agressifs pour tester la resistance du modele.
A4: Indicateur | B4: Conservateur | C4: Reference (Base) | D4: Optimiste
A5: CA - Annee 1 | B5: 1470711 | C5: 1793550 | D5: 2116389
A6: CA - Annee 2 | B6: 3132687 | C6: 3820350 | D6: 4508013
A7: CA - Annee 3 | B7: 4593927 | C7: 5602350 | D7: 6610773
A8: EBITDA - Annee 1 | B8: 38801.1 | C8: 309855 | D8: 440508.9
A9: EBITDA - Annee 2 | B9: 851587.5 | C9: 1368375 | D9: 1708762.5
A10: EBITDA - Annee 3 | B10: 1557705.9 | C10: 2298495 | D10: 2825984.1
A11: Tresorerie finale (Mois 36) | B11: 2603094.5 | C11: 4131725 | D11: 5130255.5
A14: Constats sur le modele de base :
A15: Mois d'equilibre (seuil) : 4
A16: Marge brute moyenne (annee 1) : 69.5%
A17: Solde de tresorerie final (mois 36) : ZAR 4,131,725
A18: Le scenario conservateur majore l'Opex de 5% et minore les revenus attendus de 18%.
A19: Le scenario optimiste augmente les ventes de 18% avec un Opex ajuste a +10% pour absorber le scale.

Sheet Risks_QA
A1: Gestion des Risques & Q&A
A2: Questions et objections susceptibles d'etre posees par des partenaires ou investisseurs.
A4: Type | B4: Sujet | C4: Risque / Question | D4: Response / Mitigation | E4: Responsable
A5: Risque | B5: Demande trop lente | C5: Demande trop lente | D5: Probabilite : Moyenne | Declencheur : Pipeline sous l'objectif pendant 2+ mois | Plan d'action : Maintenir des couts fixes bas, intensifier la prospection, packager une offre d'audit plus rapide | E5: CEO
A6: Risque | B6: Derive du perimetre (Scope Creep) | C6: Derive du perimetre (Scope Creep) | D6: Probabilite : Moyenne | Declencheur : Projets derivant vers du travail sur mesure | Plan d'action : Garder 3 offres productisees et appliquer une regle stricte de devis complementaire | E6: Directeur Livraison
A7: Risque | B7: Dependance au fondateur | C7: Dependance au fondateur | D7: Probabilite : Elevee | Declencheur : Toutes les ventes et la livraison dependent d'une seule personne | Plan d'action : Documenter les procedures (SOPs), deleguer la livraison, batir un vivier de partenaires | E7: CEO
A8: Risque | B8: Tension sur la tresorerie | C8: Tension sur la tresorerie | D8: Probabilite : Moyenne | Declencheur : La tresorerie nette descend sous 2 mois de frais de fonctionnement | Plan d'action : Geler les recrutements non critiques, prioriser la vente d'abonnements | E8: Finance
A9: Risque | B9: Retard fiscal / conformite | C9: Retard fiscal / conformite | D9: Probabilite : Faible | Declencheur : Declaration TVA ou publications legales en retard | Plan d'action : Suivre une checklist mensuelle et faire valider par un expert-comptable externe | E9: Ops
A10: Risque | B10: Confusion sur le positionnement | C10: Confusion sur le positionnement | D10: Probabilite : Moyenne | Declencheur : Les prospects nous considerent comme une simple agence | Plan d'action : Marteler notre narratif clair : Forge = execution, Sovereign = autonomie | E10: Marque
A11: Risque | B11: Derive de l'implementation | C11: Derive de l'implementation | D11: Probabilite : Elevee | Declencheur : Les projets d'implementation s'allongent sans garde-fous de ROI | Plan d'action : Definir les criteres de succes en amont et vendre au forfait base sur la valeur | E11: Directeur Livraison
A12: Q&A | B12: Qu'est-ce qu'Opays Tech ? | C12: Qu'est-ce qu'Opays Tech ? | D12: Un cabinet d'ingenierie de l'efficience : nous simplifions les operations, automatisons les taches repetitives et integrons l'IA uniquement la ou elle apporte une valeur mesurable. | E12: Opays
A13: Q&A | B13: Pourquoi deux branches ? | C13: Pourquoi deux branches ? | D13: Forge est le moteur de cash : diagnostics, implementation, retainers. Sovereign est le moteur d'autonomie : recherche, resilience, intelligence strategique. | E13: Opays
A14: Q&A | B14: Pourquoi maintenant ? | C14: Pourquoi maintenant ? | D14: Les entreprises subissent des pressions sur leurs couts, les equipes sont surchargees et l'adoption de l'IA reste fragmentee. Il faut passer de la hype a l'execution concrete. | E14: Opays
A15: Q&A | B15: Qu'est-ce qui rend ce modele credible ? | C15: Qu'est-ce qui rend ce modele credible ? | D15: Il est oriente services, conscient des marges, productise et fonde sur des gains operationnels reels plutot que sur des promesses vagues d'innovation. | E15: Opays
... A36: Q&A | B36: Comment gerez-vous les dossiers Sovereign ? | C36: Comment gerez-vous les dossiers Sovereign ? | D36: Comme des mandats de recherche et de conseil strategique haut de gamme, et non comme de la sous-traitance standard. | E36: Opays

Sheet Sources
A1: Sources de Conformite
A2: Sources officielles utilisees pour formuler les hypotheses de taxes et de fiscalite.
A4: Sujet | B4: Source officielle | C4: Lien (URL)
A5: TVA | B5: Page officielle de la SARS sur la TVA | C5: https://www.sars.gov.za/types-of-tax/value-added-tax/
A6: Impot sur les societes | B6: Taux standard d'IS de la SARS | C6: https://www.sars.gov.za/types-of-tax/corporate-income-tax/
A7: Exclusion taxe chiffre d'affaires | B7: Conditions de la SARS pour les services professionnels | C7: https://www.sars.gov.za/faq/faq-what-are-the-requirements-for-a-micro-business-to-qualify-for-turnover-tax/

Sheet Operations
A1: Systeme d'Exploitation
A2: C'est l'execution et le delivery standardise qui creent la valeur du cabinet, pas seulement les idees.
A4: Principes d'operation | D4: Facteur clé de succes
A5: • Une seule source de verite pour la strategie, la livraison et les decisions. | D5: L'entreprise est rentable quand le message, le processus, le prix et le rythme de livraison pointent tous dans la meme direction.
A6: • Des ajustements petits et tracables plutot que de grandes improvisations. | D6: Les investisseurs s'assurent que le cabinet peut livrer de la valeur sans reposer uniquement sur un effort heroique du fondateur.
A7: • Chaque mission client a un debut, une livraison et une sortie definis. | D7: Le but n'est pas la complexite technique, mais l'assurance d'une execution previsible.
A8: • Le fondateur se concentre sur les ventes et la qualite, pas sur les taches repetitives.
A10: Core roles
A11: • CEO / Fondateur : ventes, narratif, design strategique, validation finale de qualite.
A12: • Responsable de la Livraison : coordination des projets, respect des delais, relation client.
A13: • Recherche & R&D : travaux scientifiques, documents, analyses et synthesis.
A14: • Operations & Admin : planification, facturation, suivi administratif et hygiene documentaire.
A16: Regles de decision
A17: • Si cela ne cree pas de valeur ou ne reduit pas la friction, ce n'est pas prioritaire.
A18: • Si le perimetre (scope) change, faire un avenant ou reporter.
A19: • Si la livraison menace la marge, refondre l'offre commerciale.
A20: • Si un processus se repete 3 fois, il doit etre standardise.
A22: Cadence d'execution
... A25: • Mensuel : revue des indicateurs (KPIs), revue des prix, revue de capacite, mise a jour du journal de decisions.

Sheet Capacity
A1: Capacite de l'Equipe
A2: Logique de debits. Ce modele garde l'entreprise honnete sur ce qu'elle est en mesure de livrer physiquement.
A4: Service | B4: Heures Fondateur | C4: Heures Expert | D4: Heures Ops | E4: Total Heures | F4: Heures disponibles / mois | G4: Unites max / mois
A5: Audit / Diagnostic | B5: 12 | C5: 4 | D5: 4 | E5: 20 | F5: 80 | G5: =F5/E5
A6: Sprint d'Efficience | B6: 24 | C6: 12 | D6: 8 | E6: 44 | F6: 100 | G6: =F6/E6
A7: Projet d'Implementation | B7: 60 | C7: 30 | D7: 15 | E7: 105 | F7: 160 | G7: =F7/E7
A8: Forge Retainer (Accompagnement) | B8: 6 | C8: 3 | D8: 3 | E8: 12 | F8: 90 | G8: =F8/E8
A9: Dossier Sovereign | B9: 30 | C9: 20 | D9: 10 | E9: 60 | F9: 70 | G9: =F9/E9
A12: Interpretation | B12: Les plafonds de capacite sont volontairement conservateurs ; ils empechent le modele de revenus de presumer d'une bande passante de livraison infinie.

Sheet Delivery
A1: Parcours client (Delivery)
A2: La qualite de livraison de nos services fait notre reputation. Ce playbook structure chaque phase.
A4: Etape | B4: Responsable | C4: Criteres d'entree | D4: Criteres de sortie | E4: Livrable | F4: Duree standard
A5: Opportunite recue | B5: Fondateur | C5: Entrant, recommandation ou reponse a la prospection | D5: Qualifie ou disqualifie | E5: Opportunite enregistree dans le CRM | F5: 1 jour
A6: Appel de decouverte | B6: Fondateur | C6: Besoin reel et budget existant | D6: Probleme et objectifs compris | E6: Notes d'appel + prochaine action | F6: 30-45 min
A7: Audit / Diagnostic | B7: Fondateur + R&D | C7: Le client accepte l'offre d'entree | D7: Cartographie de friction et hypothese de ROI pretes | E7: Note d'audit et de synthese | F7: 3-10 jours
A8: Proposition / Contrat | B8: Fondateur | C8: Diagnostic complete | D8: Perimetre, tarif et planning valides | E8: Proposition commerciale + contrat signe | F8: 1-3 jours
A9: Sprint de livraison | B9: Responsable Livraison | C9: Contrat signe et acompte verse | D9: Flux de travail ou systeme cible ameliore | E9: Dossier d'implementation standard | F9: 2-6 semaines
A10: Transfert final | B10: Fondateur + Ops | C10: Criteres d'acceptation valides | D10: Le client sait utiliser le nouveau processus | E10: Note de transfert + procedure standard | F10: 1-2 jours
A11: Abonnement (Retainer) | B11: Fondateur | C11: Valeur pouvee et confirmee | D11: Accord d'optimisation recurrente signe | E11: Point mensuel de suivi operationnel | F11: Continu
A14: Regle d'or | B14: Definir les criteres de reussite en amont du projet. Ne jamais declarer un projet termine avant que le client n'ait valide la prise en main de l'outil.

Sheet Cadence
A1: Rhythme Hebdomadaire
A2: Un rythme d'execution standardise pour transformer la vision en routine.
A4: Jour | B4: Focus | C4: Actions cles | D4: Livrable
A5: Lundi | B5: Pipeline et priorites | C5: Revue des opportunites, planification client, definition des 3 objectifs de la semaine | D5: Plan d'action clair et responsabilites attribuees
A6: Mardi | B6: Livraison / Production | C6: Concentration sur les livrables clients et les modeles internes | D6: Produits livrables et shippable
A7: Mercredi | B7: Ventes & Visibilite | C7: Demarchage, LinkedIn, presse locale, relations publiques | D7: Activites de prospection
A8: Jeudi | B8: Livraison & Echanges client | C8: Points d'avancement avec les clients, suivi, QA et validations | D8: Confiance et dynamique client
A9: Vendredi | B9: Finance, Apprentissage & Admin | C9: Revue de tresorerie, facturation, journal des decisions, retour d'experience | D9: Cloture propre et preparation de la semaine suivante
A12: Regle d'or | B12: Si la semaine ne produit pas d'avancement sur le pipeline, sur la livraison ou sur la tresorerie, le rythme n'est pas bon.

Sheet SOPs
A1: Procedures standards (SOPs)
A2: Les SOPs garantissent la repetabilite et la valeur a terme du cabinet.
A4: Procedure (SOP) | B4: Objectif | C4: Declencheur | D4: Responsable | E4: Resultat attendu
A5: Qualification des leads | B5: Filtrer les opportunites viables | C5: Nouveau contact ou recommandation | D5: Fondateur | E5: Pipeline qualifie ou disqualification propre
A6: Appel de decouverte | B6: Comprendre le probleme reel | C6: Apres la qualification | D6: Fondateur | E6: Probleme defini et alignement de fit
A7: Checklist d'audit | B7: Standardiser nos diagnostics | C7: Le client achete un diagnostic | D7: Fondateur + R&D | E7: Note d'audit standardisee
A8: Modele de proposition | B8: Accelerer le suivi commercial | C8: Audit complete | D8: Fondateur | E8: Offre commerciale claire
A9: Controle du perimetre | B9: Proteger notre marge brute | C9: Toute demande de changement de perimetre | D9: Fondateur | E9: Avenant signe ou gel du perimetre
A10: Revue qualite (QA) | B10: Eviter les erreurs de livraison | C10: Avant le transfert final | D10: Responsable Livraison | E10: Livrable verifie et certifie
A11: Revue de tresorerie | B11: Proteger notre runway | C11: Chaque vendredi | D11: Fondateur + Ops | E11: Situation de tresorerie a jour et actions
A12: Journal de decisions | B12: Maintenir une gouvernance vivante | C12: Toute decision strategique | D12: Fondateur | E12: Decision consignee et datee
A15: Regle d'or | B15: Si une action complexe est executee plus d'une fois, elle doit etre documentee par une SOP.

Sheet Team
A1: Modele d'Equipe
A2: L'entreprise doit etre visible et quantifiable comme un collectif et non seulement par son fondateur.
A4: Role | B4: Responsabilite principale | C4: Statut | D4: Capacite (heures/mois) | E4: Repartition hebdomadaire | F4: Declencheur de recrutement
A5: Fénelon Lamsasiri — CEO / R&D | B5: Vision, gouvernance, strategie, validation qualite, recherche | C5: Actif | D5: 80 | E5: Strategie 30%, livraison 25%, management 25%, contenu 20% | F5: Lorsque la strategie ou la qualite depasse 80h/mois
A6: Prince Bagheni — Directeur Commercial | B6: Prospection, closing, relations partenaires, rigueur du pipeline | C6: Actif | D6: 70 | E6: Prospection 45%, suivi 30%, closing 15%, reporting 10% | F6: Lorsque le volume d'opportunites requiert un commercial dedie
A7: Patricia Zamwana — Admin & Gestion | B7: Support prospection, suivi comptable, tresorerie, soutien administratif | C7: Actif | D7: 60 | E7: Finance 40%, admin 30%, support ventes 30% | F7: Lorsque la facturation ou le suivi de tresorerie requiert un temps plein
A8: Zaina Bwale Godlove — Marque & Ventes | B8: Prospection, communication, visibilite, supports institutionnels | C8: Actif | D8: 60 | E8: Comms 40%, prospection 30%, marque 20%, support 10% | F8: Lorsque l'effort de communication ou de visibilite augmente
A9: Directeur Technique / CTO | B9: Architecture, securite, qualite technique, supervision livraison | C9: Vacant / En recrutement | D9: 0 | E9: N/A | F9: Lorsque la livraison technique requiert un responsable dedie
A10: Antigravity — IA Collaboratrice | B10: Redaction, structuration, support automatisation, aide operationnelle | C10: Actif (actif de type systeme) | D10: 40 | E10: Documents 30%, automatisation 30%, support 40% | F10: Lorsque les taches administratives ou repetitives saturent l'equipe
A12: Regle d'equipe | B12: L'entreprise grandit en capitalisant sur ses process avant d'ajouter de la masse salariale. Chaque recrutement doit soit securiser la marge, soit augmenter le debit de livraison, soit securiser le temps du fondateur.

Sheet Pipeline
A1: Modélisation du Pipeline
A2: Liaison mathematique entre l'activite de prospection, les leads et le chiffre d'affaires.
